Workbook

Sheet 00_พจนานุกรมรหัส
A1: พจนานุกรมรหัส — intervention package V.2
A2: รหัสมาตรการเปลี่ยนจาก M เป็น MS แล้วทั้งไฟล์ เพื่อไม่ให้ชนกับรหัส Ottawa (M1–M6) ในเอกสาร Flow v.1
A4: ตระกูลรหัส | B4: ความหมาย | C4: จำนวน | D4: ตัวอย่าง | E4: ใช้ในชีต
A5: S | B5: พื้นที่ดำเนินการ (ชุดของโครงการ) | C5: 3 | D5: S1 สถานศึกษา / S2 ชุมชน / S3 สถานประกอบการ | E5: 03, 04
A6: MS | B6: องค์ประกอบในโมเดล IP ของ สสส. | C6: 12 | D6: MS4 การสอดแทรกในการเรียนการสอน | E6: 01, 03, 05
A7: IP | B7: แพ็กเกจแผน (1 IP = 1 ไฟล์แผนที่ผู้ใช้ดาวน์โหลด) | C7: 9 | D7: IP-02 ห้องเรียนรู้เท่าทันบุหรี่ไฟฟ้า | E7: 03, 04, 05, 06
A8: R | B8: บทบาทผู้ใช้ระบบ (ผู้ดำเนินการ) | C8: 16 (จาก 24) | D8: R02 ครู/อาจารย์ | E8: 02, 03, 04
A9: G | B9: กลุ่มเป้าหมายปลายทาง | C9: 10 | D9: G03 นักเรียนมัธยม | E9: 02, 04
A10: T | B10: เครื่องมือในคลัง | C10: 25 (จาก 28) | D10: T18 บอร์ดเกม Just Say No | E10: 02, 04, 05
A11: SC | B11: รหัสสถานการณ์ (สร้างใหม่ใน V.2) | C11: ดูชีต 04 | D11: SC-001 | E11: 04
A14: ตารางเทียบเลขเครื่องมือ 3 ชุด
A15: รหัสที่ใช้จริง | B15: เลขในตาราง Flagship 11 พ.ค. | C15: เลขในแผนภาพโมเดล 23 มิ.ย. | D15: ชื่อเครื่องมือ | E15: สถานะ
A16: T01 | B16: 01 | C16: 1 | D16: "7 มาตรการโรงเรียนปลอดบุหรี่" / "7 องค์ประกอบ" (อุดมศึกษา) | E16: ใช้งาน
A17: T04 | B17: 04 | C17: 4 | D17: คู่มือการใช้งาน Uni-Health Platform | E17: ใช้งาน
A18: T05 | B18: 05 | C18: 5 | D18: แนวปฏิบัติมาตรฐาน (SOP Harmony) | E18: ใช้งาน
A19: T06 | B19: 06 | C19: 6 | D19: แนวปฏิบัติ "เลิกบุหรี่เริ่มที่บ้าน" / "เลิกบุหรี่บ้านละคน" | E19: ใช้งาน
A20: T07 | B20: 07 | C20: 7 | D20: แนวปฏิบัติ "มัสยิดปลอดบุหรี่" | E20: ใช้งาน
A21: T08 | B21: 08 | C21: 8 | D21: คู่มือกิจกรรมบุหรี่ไฟฟ้าสำหรับครูและผู้ปกครอง | E21: ใช้งาน
A22: T09 | B22: 09 | C22: 9 | D22: แบบทดสอบความรอบรู้ทางสุขภาพด้านการควบคุมยาสูบ | E22: ใช้งาน
A23: T10 | B23: 10 | C23: 10 | D23: Application TUM (Tobacco Use Monitor) | E23: ใช้งาน
A24: T11 | B24: 11 | C24: 11 | D24: แบบสำรวจพฤติกรรมบุหรี่และบุหรี่ไฟฟ้า | E24: ใช้งาน
A25: T12 | B25: 12 | C25: 12 | D25: แบบประเมินความรอบรู้เรื่องบุหรี่ไฟฟ้า | E25: ใช้งาน
A26: T13 | B26: 13 | C26: 13 | D26: แบบสอบถาม Uni-Health Platform | E26: ใช้งาน
... A43: T17 | B43: 17 | C43: 17 | D43: Survival Kit 7+1 | E43: ตัดชั่วคราว (อาจไม่ตรงประเด็น)

Sheet 01_มาตรการ_MS
A1: องค์ประกอบในโมเดล IP ของ สสส. (รหัส MS)
A2: เป้าหมายเป็นการสรุปของทีมจากแผนภาพโมเดล 23 มิ.ย. 69 — ต้องให้ สสส. ยืนยันถ้อยคำ
A4: รหัส MS | B4: Setting | C4: ชื่อองค์ประกอบ | D4: เป้าหมาย | E4: เครื่องมือในคลังที่รองรับ | F4: IP ที่รับไปทำต่อ
A5: MS1 | B5: สถานศึกษา | C5: มาตรการ 1 การกำหนดนโยบาย | D5: มีนโยบายสถานศึกษาปลอดบุหรี่ที่ประกาศชัดและสื่อสารทั่วถึง | E5: T01, T05 (อุดมศึกษา) | F5: IP-01
A6: MS2 | B6: สถานศึกษา | C6: มาตรการ 2 การบริหารจัดการ | D6: มีคณะทำงานขับเคลื่อนและแบ่งบทบาทฝ่ายให้งานเดินต่อเนื่อง | E6: T01 (หัวข้อภายใน), T04 (อุดมศึกษา) | F6: IP-01
A7: MS3 | B7: สถานศึกษา | C7: มาตรการ 3 การจัดการสภาพแวดล้อม | D7: พื้นที่กายภาพไม่เอื้อต่อการแอบใช้ และมีสื่อเตือนครบจุดเสี่ยง | E7: T01 (หัวข้อภายใน), T22 (ใช้เป็นสื่อติดตั้ง) | F7: IP-01
A8: MS4 | B8: สถานศึกษา | C8: มาตรการ 4 การสอดแทรกในการเรียนการสอน | D8: เด็กและเยาวชนมีความรอบรู้และทักษะปฏิเสธผ่านการเรียนการสอน | E8: T08, T16, T18, T19, T24 | F8: IP-02
A9: MS5 | B9: สถานศึกษา | C9: มาตรการ 5 การมีส่วนร่วมของนักเรียน | D9: นักเรียนเป็นฟันเฟืองหลัก มีชมรมและแกนนำที่ทำงานเองได้ | E9: T27, T20 | F9: IP-03
A10: MS6 | B10: สถานศึกษา | C10: มาตรการ 6 การดูแลช่วยเหลือนักเรียน | D10: ผู้ที่ใช้แล้วได้รับการดูแลให้ลด ละ เลิก และถูกส่งต่อเมื่อจำเป็น | E10: T19, T28, T05 (อุดมศึกษา) | F10: IP-04
A11: MS7 | B11: สถานศึกษา×ชุมชน | C11: มาตรการ 7 กิจกรรมร่วมระหว่างโรงเรียนกับชุมชน | D11: เกิดพื้นที่ปลอดบุหรี่นอกรั้วสถานศึกษาผ่านกิจกรรมร่วม | E11: T20, T22, T23 | F11: IP-07
A12: MS-F1 | B12: ครอบครัว | C12: บ้านปลอดควัน | D12: บ้านเป็นพื้นที่ปลอดควัน และคนในบ้านที่สูบได้รับการชวนให้เลิก | E12: T06, T08 | F12: IP-05
A13: MS-C1 | B13: ชุมชน | C13: วัด/มัสยิดปลอดควัน | D13: ศาสนสถานเป็นจุดตั้งต้นของพื้นที่ปลอดควันในชุมชน | E13: T07, T06 | F13: IP-06
A14: MS-C2 | B14: ชุมชน | C14: ZONING ปลอดบุหรี่ (Area-based) | D14: ชุมชนมีเขตปลอดบุหรี่และมีการเฝ้าระวังพื้นที่กับแหล่งขาย | E14: T10, T22 | F14: IP-06
A15: MS-C3 | B15: ชุมชน | C15: สื่อสารในงานชุมชนท้องถิ่น (Event-based) | D15: ใช้งานประเพณีและเทศกาลเป็นเวทีสื่อสารให้คนรู้เท่าทัน | E15: T15, T20, T21, T22, T23 | F15: IP-07
A16: MS-H1 | B16: ระบบบริการสุขภาพ | C16: เชื่อมโยงสาธารณสุข–รพ.สต. (ระบบช่วยเลิก) | D16: คนที่อยากเลิกเข้าถึงบริการช่วยเลิกได้ และมีเส้นทางส่งต่อ | E16: T28 | F16: IP-08

Sheet 02_เครื่องมือ
A1: Tool Card ครบ 25 ชิ้น
A2: ช่องขั้นตอน สิ่งที่ต้องเตรียม ความเสี่ยง เงื่อนไข ตัวชี้วัด เป็นข้อมูล [จำลอง] ทั้งหมด รอแทนที่ด้วยคู่มือจริงจาก สสส.
A4: รหัส | B4: ชื่อเครื่องมือ | C4: ประเภท | D4: คำอธิบายสั้น (ใช้บนการ์ด) | E4: กลุ่มเป้าหมาย (G) | F4: ระดับ | G4: ผู้ดำเนินการหลัก (R) | H4: ผู้ร่วม (R) | I4: สถานที่ใช้ | J4: บทบาทในแผน | K4: IP ที่ผูก | L4: ลักษณะกิจกรรม | M4: ขั้นตอนใช้งาน [จำลอง] | N4: สิ่งที่ต้องเตรียม [จำลอง] | O4: ความเสี่ยง [จำลอง] | P4: เงื่อนไขความสำเร็จ [จำลอง] | Q4: ตัวชี้วัด [จำลอง] | R4: ใช้คู่กับ | S4: ไฟล์การ์ด | T4: แหล่งที่มา | U4: สถานะข้อมูล
A5: T01 | B5: "7 มาตรการโรงเรียนปลอดบุหรี่" / "7 องค์ประกอบ" (อุดมศึกษา) | C5: คู่มือ/แนวปฏิบัติ | D5: ชุดมาตรการขับเคลื่อนสถานศึกษาปลอดบุหรี่ครบ 7 ด้าน ตั้งแต่นโยบายถึงกิจกรรมร่วมกับชุมชน | E5: G02 นักเรียนประถม; G03 นักเรียนมัธยม; G04 นักศึกษาอุดมศึกษา; | F5: ป้องกัน | G5: R01 ผู้บริหารสถานศึกษา; R08 ทีมผู้บริหารและครู | H5: R02 ครู/อาจารย์; R03 บุคลากรในสถานศึกษา; R06 แกนนำนักเรียน; R07 แกนนำนักศึกษา; R10 เจ้าหน้าที่สาธารณสุข; R11 ผู้ปกครอง | I5: ทั้งโรงเรียน / มหาวิทยาลัย | J5: หลัก | K5: IP-01 | L5: ตั้งกติกา/ระบบในองค์กร | M5: ช่วง 1 ประชุมผู้บริหารและตั้งคณะทำงาน 1 ครั้ง ช่วง 2 ประกาศนโยบายและสื่อสารให้ครู นักเรียน ผู้ปกครองรับรู้ ช่วง 3 แบ่งงาน 3 ฝ่าย ได้แก่ สถานที่ วิชาการ ปกครอง ช่วง 4 ทบทวนผลรายเดือนและรายงานคณะกรรมการสถานศึกษา | N5: คำสั่งแต่งตั้งคณะทำงาน, เวลาประชุมฝ่าย, งบป้ายและสื่อ | O5: นโยบายประกาศแล้วไม่มีคนติดตาม; จุดเสี่ยงนอกรั้วโรงเรียนควบคุมไม่ได้ | P5: ผู้บริหารกำหนดผู้รับผิดชอบชัดเจน; ทบทวนผลอย่างน้อยเดือนละครั้ง | Q5: มีประกาศนโยบายและคณะทำงาน; จำนวนจุดเสี่ยงที่ปรับปรุง; เหตุการณ์พบการใช้ในสถานศึกษา | R5: T16, T12 | S5: T01.pdf | T5: เอกสาร 7 มาตรการ (พบข้อมูลเผยแพร่) | U5: จริงบางส่วน + [จำลอง]
A6: T04 | B6: คู่มือการใช้งาน Uni-Health Platform | C6: คู่มือ/แนวปฏิบัติ | D6: คู่มือใช้แพลตฟอร์มดูแลสุขภาวะในมหาวิทยาลัยและที่ทำงาน | E6: G04 นักศึกษาอุดมศึกษา; G07 พนักงาน/วัยทำงาน; | F6: ทั้งสองระดับ | G6: R01 ผู้บริหารสถานศึกษา; R03 บุคลากรในสถานศึกษา | H6: R02 ครู/อาจารย์; R07 แกนนำนักศึกษา; R23 บุคลากรในสถานประกอบการ; R24 แกนนำในสถานประกอบการ | I6: มหาวิทยาลัย (ออนไลน์) | J6: หลัก | K6: IP-01, IP-09 | L6: ตั้งกติกา/ระบบในองค์กร | M6: ช่วง 1 เปิดใช้แพลตฟอร์มและกำหนดผู้ดูแลระบบ ช่วง 2 ประชาสัมพันธ์ให้นักศึกษา/พนักงานเข้าใช้ ช่วง 3 ติดตามข้อมูลการใช้งานรายเดือน ช่วง 4 สรุปผลเสนอผู้บริหาร | N6: บัญชีผู้ดูแลระบบ, ช่องทางประชาสัมพันธ์ภายใน | O6: คนเข้าใช้น้อยถ้าไม่มีการสื่อสารต่อเนื่อง; ข้อมูลไม่ถูกนำไปใช้ต่อ | P6: มีผู้ดูแลระบบประจำ; ผู้บริหารใช้ข้อมูลประกอบการตัดสินใจ | Q6: จำนวนผู้ลงทะเบียนใช้งาน; จำนวนเคสที่ถูกส่งต่อ | R6: T13 | S6: T04.pdf | T6: ตาราง Flagship 11 พ.ค. | U6: จริงบางส่วน + [จำลอง]
A7: T05 | B7: แนวปฏิบัติมาตรฐาน (SOP Harmony) | C7: คู่มือ/แนวปฏิบัติ | D7: ขั้นตอนปฏิบัติมาตรฐานเมื่อพบการใช้บุหรี่ไฟฟ้าในมหาวิทยาลัย | E7: G04 นักศึกษาอุดมศึกษา; | F7: ทั้งสองระดับ | G7: R01 ผู้บริหารสถานศึกษา; R03 บุคลากรในสถานศึกษา | H7: R02 ครู/อาจารย์; R07 แกนนำนักศึกษา | I7: มหาวิทยาลัย | J7: หลัก | K7: IP-01, IP-04 | L7: ตั้งกติกา/ระบบในองค์กร | M7: ช่วง 1 ทบทวนขั้นตอนเดิมของสถาบัน ช่วง 2 ประกาศใช้ SOP และอบรมผู้เกี่ยวข้อง ช่วง 3 ทดลองใช้กับเคสจริงและบันทึกผล ช่วง 4 ปรับปรุง SOP ตามผลการใช้ | N7: เอกสาร SOP, ทีมอบรม, แบบบันทึกเคส | O7: ผู้ปฏิบัติไม่รู้ขั้นตอนเมื่อเจอเคสจริง; ไม่มีผู้รับผิดชอบชัดเจน | P7: อบรมผู้เกี่ยวข้องครบทุกหน่วย; มีช่องทางส่งต่อที่ใช้ได้จริง | Q7: จำนวนผู้ผ่านการอบรม; จำนวนเคสที่ดำเนินการตาม SOP | R7: T04, T13 | S7: T05.pdf | T7: ตาราง Flagship 11 พ.ค. | U7: จริงบางส่วน + [จำลอง]
A8: T06 | B8: แนวปฏิบัติ "เลิกบุหรี่เริ่มที่บ้าน" / "เลิกบุหรี่บ้านละคน" | C8: คู่มือ/แนวปฏิบัติ | D8: ใช้ครอบครัวเป็นแรงจูงใจให้คนในบ้านลด ละ เลิกบุหรี่ | E8: G08 ประชากรกลุ่มเฉพาะ (ชุมชนมุสลิม); | F8: ทั้งสองระดับ | G8: R18 แกนนำชุมชนมุสลิม; R19 คณะกรรมการมัสยิด | H8: R11 ผู้ปกครอง; R13 แกนนำชุมชน; R15 อสม. | I8: บ้าน / มัสยิด / ตาดีกา | J8: หลัก | K8: IP-05 | L8: ช่วยคนที่อยากเลิก | M8: ช่วง 1 สำรวจครัวเรือนที่มีผู้สูบในชุมชน ช่วง 2 ชวนครอบครัวเข้าร่วมผ่านกิจกรรมของมัสยิดหรือตาดีกา ช่วง 3 ติดตามรายครัวเรือนทุก 2 สัปดาห์ ช่วง 4 ยกย่องครัวเรือนต้นแบบในเวทีชุมชน | N8: รายชื่อครัวเรือน, ทีมเยี่ยมบ้าน, สื่อให้ความรู้ | O8: ครัวเรือนไม่เปิดรับการเยี่ยม; ผู้สูบกลับไปสูบซ้ำ | P8: ผู้นำศาสนาเป็นแบบอย่าง; มีทีมติดตามต่อเนื่อง | Q8: จำนวนครัวเรือนที่เข้าร่วม; จำนวนผู้ที่ลดหรือเลิกได้ | R8: T07 | S8: T06.pdf | T8: มูลนิธิสร้างสุขมุสลิมไทย (พบข้อมูลเผยแพร่) | U8: จริงบางส่วน + [จำลอง]
A9: T07 | B9: แนวปฏิบัติ "มัสยิดปลอดบุหรี่" | C9: คู่มือ/แนวปฏิบัติ | D9: ขับเคลื่อนมัสยิดปลอดบุหรี่ด้วยหลักศาสนาและคณะกรรมการมัสยิด | E9: G08 ประชากรกลุ่มเฉพาะ (ชุมชนมุสลิม); | F9: ทั้งสองระดับ | G9: R18 แกนนำชุมชนมุสลิม; R19 คณะกรรมการมัสยิด | H9: R13 แกนนำชุมชน; R14 แกนนำ อปท.; R15 อสม. | I9: มัสยิด | J9: หลัก | K9: IP-06 | L9: ตั้งกติกา/ระบบในองค์กร | M9: ช่วง 1 ประชุมคณะกรรมการมัสยิดและประกาศเจตนารมณ์ ช่วง 2 ติดป้ายสัญลักษณ์และสื่อสารผ่านคุตบะห์ ช่วง 3 ขอความร่วมมือสัปปุรุษและร้านค้ารอบมัสยิด ช่วง 4 ทบทวนผลและขยายสู่ครัวเรือน | N9: ป้ายสัญลักษณ์, ผู้ประกาศ, วาระประชุมคณะกรรมการ | O9: ประกาศแล้วไม่มีการเฝ้าระวังต่อเนื่อง; ร้านค้ารอบพื้นที่ยังขายให้เด็ก | P9: ผู้นำศาสนาสนับสนุนเต็มที่; มีทีมเฝ้าระวังร่วมกับชุมชน | Q9: มีประกาศพื้นที่ปลอดบุหรี่; จำนวนกิจกรรมสื่อสาร; เหตุการณ์สูบในมัสยิดลดลง | R9: T06, T22 | S9: T07.pdf | T9: มูลนิธิสร้างสุขมุสลิมไทย (พบข้อมูลเผยแพร่) | U9: จริงบางส่วน + [จำลอง]
A10: T08 | B10: คู่มือกิจกรรมบุหรี่ไฟฟ้าสำหรับครูและผู้ปกครอง | C10: คู่มือ/แนวปฏิบัติ | D10: กิจกรรมเรียนรู้เรื่องบุหรี่ไฟฟ้าที่ครูและผู้ปกครองทำกับเด็กได้ | E10: G02 นักเรียนประถม; G03 นักเรียนมัธยม; | F10: ป้องกัน | G10: R02 ครู/อาจารย์; R11 ผู้ปกครอง | H10: R06 แกนนำนักเรียน; R03 บุคลากรในสถานศึกษา | I10: ห้องเรียน / บ้าน | J10: หลัก | K10: IP-02, IP-05 | L10: จัดกิจกรรมเรียนรู้ | M10: ช่วง 1 ครูศึกษาคู่มือและเลือกกิจกรรมที่เหมาะกับชั้นเรียน ช่วง 2 จัดกิจกรรมในห้องเรียน 2–3 ครั้ง ช่วง 3 ส่งใบกิจกรรมให้ผู้ปกครองทำต่อที่บ้าน ช่วง 4 สรุปผลและคืนข้อมูลให้ผู้ปกครอง | N10: คู่มือ, ใบกิจกรรม, คาบเรียน 1–2 คาบ | O10: ผู้ปกครองไม่ได้ทำกิจกรรมต่อที่บ้าน; เวลาคาบเรียนไม่พอ | P10: ครูได้อ่านคู่มือก่อนใช้; มีช่องทางสื่อสารกับผู้ปกครอง | Q10: จำนวนนักเรียนที่เข้าร่วม; ความรอบรู้ก่อน–หลัง; จำนวนครอบครัวที่ทำกิจกรรมต่อ | R10: T16, T12 | S10: T08.pdf | T10: ตาราง Flagship 11 พ.ค. | U10: จริงบางส่วน + [จำลอง]
A11: T09 | B11: แบบทดสอบความรอบรู้ทางสุขภาพด้านการควบคุมยาสูบ | C11: แบบสำรวจ/ประเมิน | D11: แบบทดสอบความรอบรู้ก่อน–หลังทำกิจกรรม | E11: G02 นักเรียนประถม; G03 นักเรียนมัธยม; G05 นักเรียนอาชีวศึกษา; G06 เยาวชนนอกระบบการศึกษา; | F11: ป้องกัน | G11: R02 ครู/อาจารย์ | H11: R03 บุคลากรในสถานศึกษา; R10 เจ้าหน้าที่สาธารณสุข | I11: สถานศึกษา / ศูนย์การเรียนรู้ | J11: วัดผล | K11: ทุก IP | L11: สำรวจสถานการณ์ | M11: ช่วง 1 แจกแบบทดสอบก่อนเริ่มกิจกรรม ช่วง 2 ดำเนินกิจกรรมตามแผน ช่วง 3 แจกแบบทดสอบซ้ำหลังจบกิจกรรม ช่วง 4 เปรียบเทียบผลและรายงาน | N11: แบบทดสอบ, เวลา 20 นาทีต่อรอบ | O11: ผู้ตอบตอบตามที่คิดว่าถูกใจครู; เก็บแบบไม่ครบ | P11: ทำทั้งก่อนและหลัง; อธิบายวัตถุประสงค์ให้ผู้ตอบเข้าใจ | Q11: คะแนนความรอบรู้ก่อน–หลัง; อัตราการตอบกลับ | R11: - | S11: T09.pdf | T11: ตาราง Flagship 11 พ.ค. | U11: จริงบางส่วน + [จำลอง]
A12: T10 | B12: Application TUM (Tobacco Use Monitor) | C12: แบบสำรวจ/ประเมิน | D12: แอปสำรวจสถานการณ์การสูบ ร้านค้า และพื้นที่สาธารณะระดับท้องถิ่น | E12: G10 ประชาชนทั่วไป; | F12: ป้องกัน | G12: R14 แกนนำ อปท. | H12: R10 เจ้าหน้าที่สาธารณสุข; R13 แกนนำชุมชน; R15 อสม. | I12: ท้องถิ่น: ครัวเรือน ร้านค้า พื้นที่สาธารณะ | J12: หลัก | K12: IP-06, IP-07 | L12: สำรวจสถานการณ์ | M12: ช่วง 1 อบรมทีมสำรวจการใช้แอป ช่วง 2 ลงพื้นที่เก็บข้อมูลร้านค้าและพื้นที่สาธารณะ ช่วง 3 สรุปข้อมูลเป็นแผนที่จุดเสี่ยง ช่วง 4 นำข้อมูลเสนอที่ประชุมท้องถิ่น | N12: โทรศัพท์มือถือ, ทีมสำรวจ 3–5 คน, แผนที่พื้นที่ | O12: ข้อมูลไม่ครบถ้าทีมสำรวจไม่ต่อเนื่อง; ร้านค้าไม่ให้ความร่วมมือ | P12: มีทีมสำรวจประจำ; ท้องถิ่นนำข้อมูลไปใช้จริง | Q12: จำนวนจุดที่สำรวจ; จำนวนจุดเสี่ยงที่ถูกจัดการ | R12: T11, T22 | S12: T10.pdf | T12: มูลนิธิรณรงค์เพื่อการไม่สูบบุหรี่ (พบข้อมูลเผยแพร่) | U12: จริงบางส่วน + [จำลอง]
A13: T11 | B13: แบบสำรวจพฤติกรรมบุหรี่และบุหรี่ไฟฟ้า | C13: แบบสำรวจ/ประเมิน | D13: แบบสำรวจพฤติกรรมเพื่อวางแผนและวัดผลก่อน–หลัง | E13: G03 นักเรียนมัธยม; G04 นักศึกษาอุดมศึกษา; G05 นักเรียนอาชีวศึกษา; G06 เยาวชนนอกระบบการศึกษา; G07 พนักงาน/วัยทำงาน; G08 ประชากรกลุ่มเฉพาะ (ชุมชนมุสลิม); G09 ผู้สูงอายุ; G10 ประชาชนทั่วไป; | F13: ป้องกัน | G13: R02 ครู/อาจารย์; R10 เจ้าหน้าที่สาธารณสุข | H13: R03 บุคลากรในสถานศึกษา; R14 แกนนำ อปท.; R15 อสม.; R23 บุคลากรในสถานประกอบการ; R24 แกนนำในสถานประกอบการ | I13: ทุกพื้นที่ | J13: วัดผล | K13: ทุก IP | L13: สำรวจสถานการณ์ | M13: ช่วง 1 กำหนดกลุ่มตัวอย่างและช่วงเวลาสำรวจ ช่วง 2 เก็บข้อมูลรอบแรก ช่วง 3 ดำเนินกิจกรรมตามแผน ช่วง 4 เก็บข้อมูลรอบสองและเปรียบเทียบ | N13: แบบสำรวจ, ทีมเก็บข้อมูล, ระบบบันทึกผล | O13: ผู้ตอบไม่ตอบตรงความจริงเรื่องการใช้; กลุ่มตัวอย่างไม่เหมือนเดิมสองรอบ | P13: เก็บข้อมูลแบบไม่ระบุตัวตน; ใช้แบบเดียวกันทั้งสองรอบ | Q13: อัตราการใช้บุหรี่ไฟฟ้าก่อน–หลัง; จำนวนผู้ตอบ | R13: - | S13: T11.pdf | T13: ตาราง Flagship 11 พ.ค. | U13: จริงบางส่วน + [จำลอง]
A14: T12 | B14: แบบประเมินความรอบรู้เรื่องบุหรี่ไฟฟ้า | C14: แบบสำรวจ/ประเมิน | D14: แบบประเมินความรอบรู้เรื่องบุหรี่ไฟฟ้าของนักเรียน | E14: G02 นักเรียนประถม; G03 นักเรียนมัธยม; | F14: ป้องกัน | G14: R02 ครู/อาจารย์ | H14: R03 บุคลากรในสถานศึกษา | I14: สถานศึกษา | J14: วัดผล | K14: ทุก IP | L14: สำรวจสถานการณ์ | M14: ช่วง 1 ประเมินก่อนเริ่มกิจกรรม ช่วง 2 ดำเนินกิจกรรมเรียนรู้ ช่วง 3 ประเมินซ้ำหลังจบ ช่วง 4 สรุปผลให้ฝ่ายวิชาการ | N14: แบบประเมิน, เวลา 15 นาทีต่อรอบ | O14: นักเรียนจำคำตอบจากรอบแรก; เก็บแบบไม่ครบ | P14: เว้นระยะระหว่างสองรอบอย่างน้อย 3 สัปดาห์ | Q14: คะแนนความรอบรู้ก่อน–หลัง | R14: - | S14: T12.pdf | T14: ตาราง Flagship 11 พ.ค. | U14: จริงบางส่วน + [จำลอง]
A15: T13 | B15: แบบสอบถาม Uni-Health Platform | C15: แบบสำรวจ/ประเมิน | D15: แบบสอบถามนักศึกษาในแพลตฟอร์ม Uni-Health | E15: G04 นักศึกษาอุดมศึกษา; | F15: ทั้งสองระดับ | G15: R03 บุคลากรในสถานศึกษา | H15: R01 ผู้บริหารสถานศึกษา; R07 แกนนำนักศึกษา | I15: มหาวิทยาลัย (ออนไลน์) | J15: วัดผล | K15: ทุก IP | L15: สำรวจสถานการณ์ | M15: ช่วง 1 เปิดแบบสอบถามในแพลตฟอร์ม ช่วง 2 ประชาสัมพันธ์ให้นักศึกษาตอบ ช่วง 3 ปิดรอบและประมวลผล ช่วง 4 เสนอผลต่อผู้บริหาร | N15: บัญชีแพลตฟอร์ม, ช่องทางประชาสัมพันธ์ | O15: จำนวนผู้ตอบน้อย; ข้อมูลไม่ถูกนำไปใช้ | P15: มีการประชาสัมพันธ์ต่อเนื่อง; ผู้บริหารใช้ข้อมูลประกอบนโยบาย | Q15: จำนวนผู้ตอบ; สัดส่วนนักศึกษาที่เคยใช้บุหรี่ไฟฟ้า | R15: T04 | S15: T13.pdf | T15: ตาราง Flagship 11 พ.ค. | U15: จริงบางส่วน + [จำลอง]
... A29: T28 | B29: สติ๊กเกอร์ลดบุหรี่ QuitUP! | C29: อุปกรณ์ | D29: สติกเกอร์ช่วยลดการใช้บุหรี่ไฟฟ้า เชื่อมเข้าสู่ระบบช่วยเลิก | E29: G10 ประชาชนทั่วไป; | F29: ดูแลคนที่ใช้แล้ว | G29: R10 เจ้าหน้าที่สาธารณสุข; R15 อสม.; R16 เภสัชกรปฐมภูมิ | H29: R06 แกนนำนักเรียน; R07 แกนนำนักศึกษา; R24 แกนนำในสถานประกอบการ | I29: จุดบริการสุขภาพ / สถานศึกษา / ชุมชน | J29: หลัก | K29: IP-04, IP-08, IP-09 | L29: ช่วยคนที่อยากเลิก | M29: ช่วง 1 เตรียมสติกเกอร์และจุดแจก ช่วง 2 แนะนำวิธีใช้ให้ผู้ที่อยากลด/เลิก ช่วง 3 ติดตามผลราย 2 สัปดาห์ ช่วง 4 ส่งต่อผู้ที่ต้องการความช่วยเหลือเพิ่มไปยังสายด่วน 1600 หรือ รพ.สต. | N29: สติกเกอร์, จุดบริการ, แบบติดตามผล | O29: ผู้ใช้เลิกกลางคัน; ไม่มีระบบติดตามต่อเนื่อง | P29: มีผู้ติดตามผลประจำ; เชื่อมกับหน่วยบริการในพื้นที่ | Q29: จำนวนผู้รับสติกเกอร์; จำนวนผู้ที่ลดหรือเลิกได้; จำนวนที่ส่งต่อ | R29: T20, T11 | S29: T28.pdf | T29: นวัตกรรมนักศึกษาอาชีวะ (พบข้อมูลเผยแพร่) | U29: จริงบางส่วน + [จำลอง]

Sheet 03_เป้าหมาย_IP
A1: 9 เป้าหมาย = 9 Intervention Package
A2: ตัวเลขสถานการณ์คำนวณจากชีต 04 อัตโนมัติ
A4: รหัส IP | B4: ชื่อแพ็กเกจ | C4: เป้าหมาย | D4: มาตรการ (MS) | E4: บทบาทที่ใช้ได้ | F4: พื้นที่ | G4: ระดับ | H4: สถานการณ์ทั้งหมด | I4: มีเครื่องมือหลัก | J4: มีเฉพาะเสริม | K4: ไม่มีเครื่องมือ | L4: ไฟล์แผน | M4: ข้อจำกัดที่ต้องบอกผู้ใช้
A5: IP-01 | B5: สถานศึกษาปลอดบุหรี่ไฟฟ้าทั้งระบบ | C5: สถานศึกษามีนโยบาย คณะทำงาน และสภาพแวดล้อมที่ไม่เอื้อต่อการใช้บุหรี่ไฟฟ้า | D5: MS1, MS2, MS3 | E5: R01 ผู้บริหารสถานศึกษา; R03 บุคลากรในสถานศึกษา; R08 ทีมผู้บริหารและครู | F5: สถานศึกษา (ทั้งโรงเรียน/มหาวิทยาลัย) | G5: ป้องกัน (อุดมศึกษาครอบคลุมการดูแลผู้ที่ใช้แล้วด้วย) | H5: =COUNTIF(04_สถานการณ์!$B$5:$B$58,"IP-01") -> 8 | I5: =COUNTIFS(04_สถานการณ์!$B$5:$B$58,"IP-01",04_สถานการณ์!$L$5:$L$58,"มีเครื่องมือหลัก") -> 8 | J5: =COUNTIFS(04_สถานการณ์!$B$5:$B$58,"IP-01",04_สถานการณ์!$L$5:$L$58,"มีเฉพาะเครื่องมือเสริม") -> 0 | K5: =COUNTIFS(04_สถานการณ์!$B$5:$B$58,"IP-01",04_สถานการณ์!$L$5:$L$58,"ไม่มีเครื่องมือในคลัง") -> 0 | L5: IP-01.pdf | M5: มาตรการ MS2 และ MS3 ไม่มีเครื่องมือเฉพาะ ต้องใช้หัวข้อภายใน T01
A6: IP-02 | B6: ห้องเรียนรู้เท่าทันบุหรี่ไฟฟ้า | C6: เด็กและเยาวชนมีความรอบรู้และทักษะปฏิเสธเมื่อถูกชักชวน | D6: MS4 | E6: R02 ครู/อาจารย์; R06 แกนนำนักเรียน | F6: สถานศึกษา (ห้องเรียน/ศพด.) | G6: ป้องกัน (กลุ่มอาชีวะใช้ระดับดูแลผู้ที่ใช้แล้ว) | H6: =COUNTIF(04_สถานการณ์!$B$5:$B$58,"IP-02") -> 6 | I6: =COUNTIFS(04_สถานการณ์!$B$5:$B$58,"IP-02",04_สถานการณ์!$L$5:$L$58,"มีเครื่องมือหลัก") -> 5 | J6: =COUNTIFS(04_สถานการณ์!$B$5:$B$58,"IP-02",04_สถานการณ์!$L$5:$L$58,"มีเฉพาะเครื่องมือเสริม") -> 1 | K6: =COUNTIFS(04_สถานการณ์!$B$5:$B$58,"IP-02",04_สถานการณ์!$L$5:$L$58,"ไม่มีเครื่องมือในคลัง") -> 0 | L6: IP-02.pdf | M6: ไม่มีเครื่องมือการเรียนการสอนสำหรับอุดมศึกษา
A7: IP-03 | B7: แกนนำเยาวชนขับเคลื่อนเอง | C7: มีชมรมหรือแกนนำที่ออกแบบและจัดกิจกรรมเรื่องบุหรี่ไฟฟ้าได้เอง | D7: MS5 | E7: R06 แกนนำนักเรียน; R07 แกนนำนักศึกษา | F7: สถานศึกษา / ชมรม | G7: ป้องกัน | H7: =COUNTIF(04_สถานการณ์!$B$5:$B$58,"IP-03") -> 2 | I7: =COUNTIFS(04_สถานการณ์!$B$5:$B$58,"IP-03",04_สถานการณ์!$L$5:$L$58,"มีเครื่องมือหลัก") -> 2 | J7: =COUNTIFS(04_สถานการณ์!$B$5:$B$58,"IP-03",04_สถานการณ์!$L$5:$L$58,"มีเฉพาะเครื่องมือเสริม") -> 0 | K7: =COUNTIFS(04_สถานการณ์!$B$5:$B$58,"IP-03",04_สถานการณ์!$L$5:$L$58,"ไม่มีเครื่องมือในคลัง") -> 0 | L7: IP-03.pdf | M7: ไม่มีคู่มือขั้นตอนการตั้งชมรมในคลัง
A8: IP-04 | B8: ดูแลช่วยเหลือผู้ที่ใช้แล้วในสถานศึกษา | C8: ผู้ที่เริ่มใช้หรือใช้แล้วได้รับการดูแลให้ลด ละ เลิก และถูกส่งต่อเมื่อจำเป็น | D8: MS6 | E8: R02 ครู/อาจารย์; R03 บุคลากรในสถานศึกษา; R06 แกนนำนักเรียน; R07 แกนนำนักศึกษา | F8: สถานศึกษา → ส่งต่อ รพ.สต./สายด่วน 1600 | G8: ดูแลคนที่ใช้แล้ว | H8: =COUNTIF(04_สถานการณ์!$B$5:$B$58,"IP-04") -> 6 | I8: =COUNTIFS(04_สถานการณ์!$B$5:$B$58,"IP-04",04_สถานการณ์!$L$5:$L$58,"มีเครื่องมือหลัก") -> 2 | J8: =COUNTIFS(04_สถานการณ์!$B$5:$B$58,"IP-04",04_สถานการณ์!$L$5:$L$58,"มีเฉพาะเครื่องมือเสริม") -> 2 | K8: =COUNTIFS(04_สถานการณ์!$B$5:$B$58,"IP-04",04_สถานการณ์!$L$5:$L$58,"ไม่มีเครื่องมือในคลัง") -> 2 | L8: IP-04.pdf | M8: นักเรียนมัธยมยังไม่มีเครื่องมือระดับดูแลผู้ที่ใช้แล้วโดยตรง
A9: IP-05 | B9: บ้านปลอดควัน ครอบครัวช่วยเลิก | C9: บ้านเป็นพื้นที่ปลอดควัน และคนในบ้านที่สูบได้รับการชวนให้ลด ละ เลิก | D9: MS-F1 | E9: R11 ผู้ปกครอง; R18 แกนนำชุมชนมุสลิม; R19 คณะกรรมการมัสยิด | F9: ครอบครัว / บ้าน | G9: ทั้งป้องกันและดูแลคนที่ใช้แล้ว | H9: =COUNTIF(04_สถานการณ์!$B$5:$B$58,"IP-05") -> 7 | I9: =COUNTIFS(04_สถานการณ์!$B$5:$B$58,"IP-05",04_สถานการณ์!$L$5:$L$58,"มีเครื่องมือหลัก") -> 6 | J9: =COUNTIFS(04_สถานการณ์!$B$5:$B$58,"IP-05",04_สถานการณ์!$L$5:$L$58,"มีเฉพาะเครื่องมือเสริม") -> 0 | K9: =COUNTIFS(04_สถานการณ์!$B$5:$B$58,"IP-05",04_สถานการณ์!$L$5:$L$58,"ไม่มีเครื่องมือในคลัง") -> 1 | L9: IP-05.pdf | M9: ไม่มีเครื่องมือสำหรับเด็กเล็กที่บ้าน หลังตัด T17
A10: IP-06 | B10: ชุมชนและศาสนสถานปลอดบุหรี่ไฟฟ้า | C10: ชุมชนมีเขตปลอดบุหรี่ที่ประกาศชัด และมีการเฝ้าระวังพื้นที่กับแหล่งขายรอบพื้นที่เด็ก | D10: MS-C1, MS-C2 | E10: R13 แกนนำชุมชน; R14 แกนนำ อปท.; R18 แกนนำชุมชนมุสลิม; R19 คณะกรรมการมัสยิด | F10: ชุมชน / วัด / มัสยิด | G10: ทั้งป้องกันและดูแลคนที่ใช้แล้ว | H10: =COUNTIF(04_สถานการณ์!$B$5:$B$58,"IP-06") -> 10 | I10: =COUNTIFS(04_สถานการณ์!$B$5:$B$58,"IP-06",04_สถานการณ์!$L$5:$L$58,"มีเครื่องมือหลัก") -> 7 | J10: =COUNTIFS(04_สถานการณ์!$B$5:$B$58,"IP-06",04_สถานการณ์!$L$5:$L$58,"มีเฉพาะเครื่องมือเสริม") -> 3 | K10: =COUNTIFS(04_สถานการณ์!$B$5:$B$58,"IP-06",04_สถานการณ์!$L$5:$L$58,"ไม่มีเครื่องมือในคลัง") -> 0 | L10: IP-06.pdf | M10: ไม่มีเครื่องมือเฝ้าระวังร้านค้าและออนไลน์ หลังตัด T02 และ T03 และไม่มีแนวปฏิบัติสำหรับวัด
A11: IP-07 | B11: สื่อสารรณรงค์ในงานและเทศกาลชุมชน | C11: คนในชุมชนรู้เท่าทันกลลวงบุหรี่ไฟฟ้า ผ่านเวทีงานประเพณีและกิจกรรมร่วมโรงเรียน–ชุมชน | D11: MS-C3, MS7 | E11: R10 เจ้าหน้าที่สาธารณสุข; R13 แกนนำชุมชน; R14 แกนนำ อปท.; R15 อสม. | F11: ชุมชน / งานประเพณี / โรงเรียน | G11: ทั้งป้องกันและดูแลคนที่ใช้แล้ว | H11: =COUNTIF(04_สถานการณ์!$B$5:$B$58,"IP-07") -> 8 | I11: =COUNTIFS(04_สถานการณ์!$B$5:$B$58,"IP-07",04_สถานการณ์!$L$5:$L$58,"มีเครื่องมือหลัก") -> 6 | J11: =COUNTIFS(04_สถานการณ์!$B$5:$B$58,"IP-07",04_สถานการณ์!$L$5:$L$58,"มีเฉพาะเครื่องมือเสริม") -> 2 | K11: =COUNTIFS(04_สถานการณ์!$B$5:$B$58,"IP-07",04_สถานการณ์!$L$5:$L$58,"ไม่มีเครื่องมือในคลัง") -> 0 | L11: IP-07.pdf | M11: ไม่ทราบวิธียืมชุดนิทรรศการและจำนวนชุดที่มี
A12: IP-08 | B12: เชื่อมระบบช่วยเลิกในระบบบริการสุขภาพ | C12: คนที่อยากเลิกเข้าถึงบริการช่วยเลิกได้จริง และมีเส้นทางส่งต่อจากโรงเรียนและชุมชน | D12: MS-H1 | E12: R10 เจ้าหน้าที่สาธารณสุข; R15 อสม.; R16 เภสัชกรปฐมภูมิ | F12: ระบบบริการสุขภาพ / รพ.สต. | G12: ดูแลคนที่ใช้แล้ว | H12: =COUNTIF(04_สถานการณ์!$B$5:$B$58,"IP-08") -> 3 | I12: =COUNTIFS(04_สถานการณ์!$B$5:$B$58,"IP-08",04_สถานการณ์!$L$5:$L$58,"มีเครื่องมือหลัก") -> 3 | J12: =COUNTIFS(04_สถานการณ์!$B$5:$B$58,"IP-08",04_สถานการณ์!$L$5:$L$58,"มีเฉพาะเครื่องมือเสริม") -> 0 | K12: =COUNTIFS(04_สถานการณ์!$B$5:$B$58,"IP-08",04_สถานการณ์!$L$5:$L$58,"ไม่มีเครื่องมือในคลัง") -> 0 | L12: IP-08.pdf | M12: มีเครื่องมือเดียวคือ T28 และไม่มีแนวทางบำบัดหรือติดตามผลในคลัง
A13: IP-09 | B13: สถานประกอบการปลอดบุหรี่ไฟฟ้า | C13: พนักงานรู้เท่าทันบุหรี่ไฟฟ้า และที่ทำงานมีแนวปฏิบัติเรื่องนี้ | D13: ไม่มีในโมเดล | E13: R23 บุคลากรในสถานประกอบการ; R24 แกนนำในสถานประกอบการ | F13: สถานประกอบการ | G13: ป้องกันเป็นหลัก (ระดับดูแลผู้ที่ใช้แล้วยังขาดเครื่องมือ) | H13: =COUNTIF(04_สถานการณ์!$B$5:$B$58,"IP-09") -> 4 | I13: =COUNTIFS(04_สถานการณ์!$B$5:$B$58,"IP-09",04_สถานการณ์!$L$5:$L$58,"มีเครื่องมือหลัก") -> 2 | J13: =COUNTIFS(04_สถานการณ์!$B$5:$B$58,"IP-09",04_สถานการณ์!$L$5:$L$58,"มีเฉพาะเครื่องมือเสริม") -> 2 | K13: =COUNTIFS(04_สถานการณ์!$B$5:$B$58,"IP-09",04_สถานการณ์!$L$5:$L$58,"ไม่มีเครื่องมือในคลัง") -> 0 | L13: IP-09.pdf | M13: ไม่มีในโมเดล IP และไม่มีเครื่องมือระดับดูแลผู้ที่ใช้แล้วสำหรับวัยทำงาน

Sheet 04_สถานการณ์
A1: สถานการณ์ครบทุกช่อง (IP × กลุ่มเป้าหมาย × บทบาท × ระดับ)
A2: ไล่ทุกชุดค่าผสมที่เป็นไปได้ ช่องที่ไม่มีเครื่องมือเขียนว่า 'ไม่มีเครื่องมือในคลัง' ไม่เว้นว่าง
A4: รหัส | B4: IP | C4: ชุด | D4: บทบาท (R) | E4: กลุ่มเป้าหมาย (G) | F4: ระดับ | G4: ลักษณะกิจกรรม | H4: ① เครื่องมือหลัก | I4: ② เครื่องมือเสริม | J4: ③ เครื่องมือวัดผล | K4: ④ อ้างอิง | L4: สถานะ | M4: หมายเหตุ | N4: ไฟล์แผน
A5: SC-001 | B5: IP-01 | C5: S1 | D5: R01 ผู้บริหารสถานศึกษา | E5: G02 นักเรียนประถม | F5: ป้องกัน | G5: ตั้งกติกา/ระบบในองค์กร | H5: T01 7 มาตรการโรงเรียนปลอดบุหรี่ / 7 องค์ประกอบ (อุดมศึกษา) | I5: ไม่มีเครื่องมือในคลัง | J5: ไม่มีเครื่องมือในคลัง | K5: - | L5: มีเครื่องมือหลัก | N5: IP-01.pdf
A6: SC-002 | B6: IP-01 | C6: S1 | D6: R01 ผู้บริหารสถานศึกษา | E6: G03 นักเรียนมัธยม | F6: ป้องกัน | G6: ตั้งกติกา/ระบบในองค์กร | H6: T01 7 มาตรการโรงเรียนปลอดบุหรี่ / 7 องค์ประกอบ (อุดมศึกษา) | I6: ไม่มีเครื่องมือในคลัง | J6: ไม่มีเครื่องมือในคลัง | K6: - | L6: มีเครื่องมือหลัก | N6: IP-01.pdf
A7: SC-003 | B7: IP-01 | C7: S1 | D7: R01 ผู้บริหารสถานศึกษา | E7: G04 นักศึกษาอุดมศึกษา | F7: ป้องกัน | G7: ตั้งกติกา/ระบบในองค์กร | H7: T01 7 มาตรการโรงเรียนปลอดบุหรี่ / 7 องค์ประกอบ (อุดมศึกษา); T04 คู่มือการใช้งาน Uni-Health Platform; T05 แนวปฏิบัติมาตรฐาน (SOP Harmony) | I7: ไม่มีเครื่องมือในคลัง | J7: T13 แบบสอบถาม Uni-Health Platform | K7: - | L7: มีเครื่องมือหลัก | N7: IP-01.pdf
A8: SC-004 | B8: IP-01 | C8: S1 | D8: R01 ผู้บริหารสถานศึกษา | E8: G04 นักศึกษาอุดมศึกษา | F8: ดูแลคนที่ใช้แล้ว | G8: ตั้งกติกา/ระบบในองค์กร | H8: T04 คู่มือการใช้งาน Uni-Health Platform; T05 แนวปฏิบัติมาตรฐาน (SOP Harmony) | I8: ไม่มีเครื่องมือในคลัง | J8: T13 แบบสอบถาม Uni-Health Platform | K8: - | L8: มีเครื่องมือหลัก | N8: IP-01.pdf
A9: SC-005 | B9: IP-01 | C9: S1 | D9: R08 ทีมผู้บริหารและครู | E9: G02 นักเรียนประถม | F9: ป้องกัน | G9: ตั้งกติกา/ระบบในองค์กร | H9: T01 7 มาตรการโรงเรียนปลอดบุหรี่ / 7 องค์ประกอบ (อุดมศึกษา) | I9: ไม่มีเครื่องมือในคลัง | J9: ไม่มีเครื่องมือในคลัง | K9: - | L9: มีเครื่องมือหลัก | N9: IP-01.pdf
A10: SC-006 | B10: IP-01 | C10: S1 | D10: R08 ทีมผู้บริหารและครู | E10: G03 นักเรียนมัธยม | F10: ป้องกัน | G10: ตั้งกติกา/ระบบในองค์กร | H10: T01 7 มาตรการโรงเรียนปลอดบุหรี่ / 7 องค์ประกอบ (อุดมศึกษา) | I10: ไม่มีเครื่องมือในคลัง | J10: ไม่มีเครื่องมือในคลัง | K10: - | L10: มีเครื่องมือหลัก | N10: IP-01.pdf
A11: SC-007 | B11: IP-01 | C11: S1 | D11: R03 บุคลากรในสถานศึกษา | E11: G04 นักศึกษาอุดมศึกษา | F11: ป้องกัน | G11: ตั้งกติกา/ระบบในองค์กร | H11: T04 คู่มือการใช้งาน Uni-Health Platform; T05 แนวปฏิบัติมาตรฐาน (SOP Harmony) | I11: T01 7 มาตรการโรงเรียนปลอดบุหรี่ / 7 องค์ประกอบ (อุดมศึกษา) | J11: T11 แบบสำรวจพฤติกรรมบุหรี่และบุหรี่ไฟฟ้า; T13 แบบสอบถาม Uni-Health Platform; T14 แบบประเมินความรู้ด้านสุขภาวะฯ สำหรับเยาวชนกลุ่มชาติพันธุ์ | K11: - | L11: มีเครื่องมือหลัก | N11: IP-01.pdf
A12: SC-008 | B12: IP-01 | C12: S1 | D12: R03 บุคลากรในสถานศึกษา | E12: G04 นักศึกษาอุดมศึกษา | F12: ดูแลคนที่ใช้แล้ว | G12: ตั้งกติกา/ระบบในองค์กร | H12: T04 คู่มือการใช้งาน Uni-Health Platform; T05 แนวปฏิบัติมาตรฐาน (SOP Harmony) | I12: ไม่มีเครื่องมือในคลัง | J12: T13 แบบสอบถาม Uni-Health Platform | K12: - | L12: มีเครื่องมือหลัก | N12: IP-01.pdf
A13: SC-009 | B13: IP-02 | C13: S1 | D13: R02 ครู/อาจารย์ | E13: G01 เด็กเล็ก (ศพด.) | F13: ป้องกัน | G13: จัดกิจกรรมเรียนรู้ | H13: T24 แผนการจัดการเรียนรู้เตือนภัยบุหรี่ไฟฟ้า สำหรับครู ศพด. | I13: ไม่มีเครื่องมือในคลัง | J13: ไม่มีเครื่องมือในคลัง | K13: - | L13: มีเครื่องมือหลัก | N13: IP-02.pdf
A14: SC-010 | B14: IP-02 | C14: S1 | D14: R02 ครู/อาจารย์ | E14: G02 นักเรียนประถม | F14: ป้องกัน | G14: จัดกิจกรรมเรียนรู้ | H14: T08 คู่มือกิจกรรมบุหรี่ไฟฟ้าสำหรับครูและผู้ปกครอง; T16 Child Impact Platform | I14: ไม่มีเครื่องมือในคลัง | J14: T09 แบบทดสอบความรอบรู้ทางสุขภาพด้านการควบคุมยาสูบ; T12 แบบประเมินความรอบรู้เรื่องบุหรี่ไฟฟ้า | K14: - | L14: มีเครื่องมือหลัก | N14: IP-02.pdf
A15: SC-011 | B15: IP-02 | C15: S1 | D15: R02 ครู/อาจารย์ | E15: G03 นักเรียนมัธยม | F15: ป้องกัน | G15: จัดกิจกรรมเรียนรู้ | H15: T08 คู่มือกิจกรรมบุหรี่ไฟฟ้าสำหรับครูและผู้ปกครอง; T16 Child Impact Platform; T18 บอร์ดเกม Just Say No | I15: ไม่มีเครื่องมือในคลัง | J15: T09 แบบทดสอบความรอบรู้ทางสุขภาพด้านการควบคุมยาสูบ; T11 แบบสำรวจพฤติกรรมบุหรี่และบุหรี่ไฟฟ้า; T12 แบบประเมินความรอบรู้เรื่องบุหรี่ไฟฟ้า; T14 แบบประเมินความรู้ด้านสุขภาวะฯ สำหรับเยาวชนกลุ่มชาติพันธุ์ | K15: - | L15: มีเครื่องมือหลัก | N15: IP-02.pdf
A16: SC-012 | B16: IP-02 | C16: S1 | D16: R02 ครู/อาจารย์ | E16: G05 นักเรียนอาชีวศึกษา | F16: ดูแลคนที่ใช้แล้ว | G16: จัดกิจกรรมเรียนรู้ | H16: T19 Vape Truth Mirror | I16: ไม่มีเครื่องมือในคลัง | J16: ไม่มีเครื่องมือในคลัง | K16: - | L16: มีเครื่องมือหลัก | N16: IP-02.pdf
A17: SC-013 | B17: IP-02 | C17: S1 | D17: R06 แกนนำนักเรียน | E17: G03 นักเรียนมัธยม | F17: ป้องกัน | G17: จัดกิจกรรมเรียนรู้ | H17: T18 บอร์ดเกม Just Say No | I17: T08 คู่มือกิจกรรมบุหรี่ไฟฟ้าสำหรับครูและผู้ปกครอง; T16 Child Impact Platform | J17: ไม่มีเครื่องมือในคลัง | K17: - | L17: มีเครื่องมือหลัก | N17: IP-02.pdf
A18: SC-014 | B18: IP-02 | C18: S1 | D18: R06 แกนนำนักเรียน | E18: G05 นักเรียนอาชีวศึกษา | F18: ดูแลคนที่ใช้แล้ว | G18: จัดกิจกรรมเรียนรู้ | H18: ไม่มีเครื่องมือในคลัง | I18: T19 Vape Truth Mirror | J18: ไม่มีเครื่องมือในคลัง | K18: - | L18: มีเฉพาะเครื่องมือเสริม | M18: บทบาทนี้เป็นผู้ร่วม ไม่ใช่ผู้เริ่ม ระบบควรแนะนำให้ชวนผู้ดำเนินการหลักมาร่วมด้วย | N18: IP-02.pdf
A19: SC-015 | B19: IP-03 | C19: S1 | D19: R06 แกนนำนักเรียน | E19: G03 นักเรียนมัธยม | F19: ป้องกัน | G19: ตั้งกลุ่ม/ชมรม, สื่อสารรณรงค์ | H19: T20 สื่อรณรงค์บุหรี่ไฟฟ้า และเผยแพร่ช่องทางเลิกบุหรี่ไฟฟ้า; T27 Youth Club เด็กมีภูมิ | I19: ไม่มีเครื่องมือในคลัง | J19: ไม่มีเครื่องมือในคลัง | K19: - | L19: มีเครื่องมือหลัก | N19: IP-03.pdf
A20: SC-016 | B20: IP-03 | C20: S1 | D20: R07 แกนนำนักศึกษา | E20: G04 นักศึกษาอุดมศึกษา | F20: ป้องกัน | G20: ตั้งกลุ่ม/ชมรม | H20: T27 Youth Club เด็กมีภูมิ | I20: ไม่มีเครื่องมือในคลัง | J20: T13 แบบสอบถาม Uni-Health Platform | K20: - | L20: มีเครื่องมือหลัก | N20: IP-03.pdf
A21: SC-017 | B21: IP-04 | C21: S1 | D21: R02 ครู/อาจารย์ | E21: G03 นักเรียนมัธยม | F21: ดูแลคนที่ใช้แล้ว | G21: - | H21: ไม่มีเครื่องมือในคลัง | I21: ไม่มีเครื่องมือในคลัง | J21: ไม่มีเครื่องมือในคลัง | K21: - | L21: ไม่มีเครื่องมือในคลัง | M21: ช่องว่างของคลัง ต้องขอเครื่องมือเพิ่มจาก สสส. | N21: IP-04.pdf
A22: SC-018 | B22: IP-04 | C22: S1 | D22: R02 ครู/อาจารย์ | E22: G05 นักเรียนอาชีวศึกษา | F22: ดูแลคนที่ใช้แล้ว | G22: จัดกิจกรรมเรียนรู้ | H22: T19 Vape Truth Mirror | I22: ไม่มีเครื่องมือในคลัง | J22: ไม่มีเครื่องมือในคลัง | K22: - | L22: มีเครื่องมือหลัก | N22: IP-04.pdf
A23: SC-019 | B23: IP-04 | C23: S1 | D23: R03 บุคลากรในสถานศึกษา | E23: G04 นักศึกษาอุดมศึกษา | F23: ดูแลคนที่ใช้แล้ว | G23: ตั้งกติกา/ระบบในองค์กร | H23: T05 แนวปฏิบัติมาตรฐาน (SOP Harmony) | I23: ไม่มีเครื่องมือในคลัง | J23: T13 แบบสอบถาม Uni-Health Platform | K23: - | L23: มีเครื่องมือหลัก | N23: IP-04.pdf
A24: SC-020 | B24: IP-04 | C24: S1 | D24: R06 แกนนำนักเรียน | E24: G03 นักเรียนมัธยม | F24: ดูแลคนที่ใช้แล้ว | G24: - | H24: ไม่มีเครื่องมือในคลัง | I24: ไม่มีเครื่องมือในคลัง | J24: ไม่มีเครื่องมือในคลัง | K24: - | L24: ไม่มีเครื่องมือในคลัง | M24: ช่องว่างของคลัง ต้องขอเครื่องมือเพิ่มจาก สสส. | N24: IP-04.pdf
A25: SC-021 | B25: IP-04 | C25: S1 | D25: R06 แกนนำนักเรียน | E25: G05 นักเรียนอาชีวศึกษา | F25: ดูแลคนที่ใช้แล้ว | G25: จัดกิจกรรมเรียนรู้ | H25: ไม่มีเครื่องมือในคลัง | I25: T19 Vape Truth Mirror | J25: ไม่มีเครื่องมือในคลัง | K25: - | L25: มีเฉพาะเครื่องมือเสริม | M25: บทบาทนี้เป็นผู้ร่วม ไม่ใช่ผู้เริ่ม ระบบควรแนะนำให้ชวนผู้ดำเนินการหลักมาร่วมด้วย | N25: IP-04.pdf
A26: SC-022 | B26: IP-04 | C26: S1 | D26: R07 แกนนำนักศึกษา | E26: G04 นักศึกษาอุดมศึกษา | F26: ดูแลคนที่ใช้แล้ว | G26: ตั้งกติกา/ระบบในองค์กร | H26: ไม่มีเครื่องมือในคลัง | I26: T05 แนวปฏิบัติมาตรฐาน (SOP Harmony) | J26: T13 แบบสอบถาม Uni-Health Platform | K26: - | L26: มีเฉพาะเครื่องมือเสริม | M26: บทบาทนี้เป็นผู้ร่วม ไม่ใช่ผู้เริ่ม ระบบควรแนะนำให้ชวนผู้ดำเนินการหลักมาร่วมด้วย | N26: IP-04.pdf
A27: SC-023 | B27: IP-05 | C27: S2 | D27: R11 ผู้ปกครอง | E27: G01 เด็กเล็ก (ศพด.) | F27: ป้องกัน | G27: - | H27: ไม่มีเครื่องมือในคลัง | I27: ไม่มีเครื่องมือในคลัง | J27: ไม่มีเครื่องมือในคลัง | K27: - | L27: ไม่มีเครื่องมือในคลัง | M27: ช่องว่างของคลัง ต้องขอเครื่องมือเพิ่มจาก สสส. | N27: IP-05.pdf
A28: SC-024 | B28: IP-05 | C28: S2 | D28: R11 ผู้ปกครอง | E28: G02 นักเรียนประถม | F28: ป้องกัน | G28: จัดกิจกรรมเรียนรู้ | H28: T08 คู่มือกิจกรรมบุหรี่ไฟฟ้าสำหรับครูและผู้ปกครอง | I28: ไม่มีเครื่องมือในคลัง | J28: ไม่มีเครื่องมือในคลัง | K28: - | L28: มีเครื่องมือหลัก | N28: IP-05.pdf
A29: SC-025 | B29: IP-05 | C29: S2 | D29: R11 ผู้ปกครอง | E29: G03 นักเรียนมัธยม | F29: ป้องกัน | G29: จัดกิจกรรมเรียนรู้ | H29: T08 คู่มือกิจกรรมบุหรี่ไฟฟ้าสำหรับครูและผู้ปกครอง | I29: ไม่มีเครื่องมือในคลัง | J29: ไม่มีเครื่องมือในคลัง | K29: - | L29: มีเครื่องมือหลัก | N29: IP-05.pdf
A30: SC-026 | B30: IP-05 | C30: S2 | D30: R18 แกนนำชุมชนมุสลิม | E30: G08 ประชากรกลุ่มเฉพาะ (ชุมชนมุสลิม) | F30: ป้องกัน | G30: ช่วยคนที่อยากเลิก | H30: T06 แนวปฏิบัติ เลิกบุหรี่เริ่มที่บ้าน / เลิกบุหรี่บ้านละคน | I30: ไม่มีเครื่องมือในคลัง | J30: ไม่มีเครื่องมือในคลัง | K30: - | L30: มีเครื่องมือหลัก | N30: IP-05.pdf
A31: SC-027 | B31: IP-05 | C31: S2 | D31: R18 แกนนำชุมชนมุสลิม | E31: G08 ประชากรกลุ่มเฉพาะ (ชุมชนมุสลิม) | F31: ดูแลคนที่ใช้แล้ว | G31: ช่วยคนที่อยากเลิก | H31: T06 แนวปฏิบัติ เลิกบุหรี่เริ่มที่บ้าน / เลิกบุหรี่บ้านละคน | I31: ไม่มีเครื่องมือในคลัง | J31: ไม่มีเครื่องมือในคลัง | K31: - | L31: มีเครื่องมือหลัก | N31: IP-05.pdf
A32: SC-028 | B32: IP-05 | C32: S2 | D32: R19 คณะกรรมการมัสยิด | E32: G08 ประชากรกลุ่มเฉพาะ (ชุมชนมุสลิม) | F32: ป้องกัน | G32: ช่วยคนที่อยากเลิก | H32: T06 แนวปฏิบัติ เลิกบุหรี่เริ่มที่บ้าน / เลิกบุหรี่บ้านละคน | I32: ไม่มีเครื่องมือในคลัง | J32: ไม่มีเครื่องมือในคลัง | K32: - | L32: มีเครื่องมือหลัก | N32: IP-05.pdf
A33: SC-029 | B33: IP-05 | C33: S2 | D33: R19 คณะกรรมการมัสยิด | E33: G08 ประชากรกลุ่มเฉพาะ (ชุมชนมุสลิม) | F33: ดูแลคนที่ใช้แล้ว | G33: ช่วยคนที่อยากเลิก | H33: T06 แนวปฏิบัติ เลิกบุหรี่เริ่มที่บ้าน / เลิกบุหรี่บ้านละคน | I33: ไม่มีเครื่องมือในคลัง | J33: ไม่มีเครื่องมือในคลัง | K33: - | L33: มีเครื่องมือหลัก | N33: IP-05.pdf
A34: SC-030 | B34: IP-06 | C34: S2 | D34: R13 แกนนำชุมชน | E34: G08 ประชากรกลุ่มเฉพาะ (ชุมชนมุสลิม) | F34: ป้องกัน | G34: ตั้งกติกา/ระบบในองค์กร | H34: ไม่มีเครื่องมือในคลัง | I34: T07 แนวปฏิบัติ มัสยิดปลอดบุหรี่ | J34: ไม่มีเครื่องมือในคลัง | K34: - | L34: มีเฉพาะเครื่องมือเสริม | M34: บทบาทนี้เป็นผู้ร่วม ไม่ใช่ผู้เริ่ม ระบบควรแนะนำให้ชวนผู้ดำเนินการหลักมาร่วมด้วย | N34: IP-06.pdf
A35: SC-031 | B35: IP-06 | C35: S2 | D35: R13 แกนนำชุมชน | E35: G08 ประชากรกลุ่มเฉพาะ (ชุมชนมุสลิม) | F35: ดูแลคนที่ใช้แล้ว | G35: ตั้งกติกา/ระบบในองค์กร | H35: ไม่มีเครื่องมือในคลัง | I35: T07 แนวปฏิบัติ มัสยิดปลอดบุหรี่ | J35: ไม่มีเครื่องมือในคลัง | K35: - | L35: มีเฉพาะเครื่องมือเสริม | M35: บทบาทนี้เป็นผู้ร่วม ไม่ใช่ผู้เริ่ม ระบบควรแนะนำให้ชวนผู้ดำเนินการหลักมาร่วมด้วย | N35: IP-06.pdf
A36: SC-032 | B36: IP-06 | C36: S2 | D36: R13 แกนนำชุมชน | E36: G10 ประชาชนทั่วไป | F36: ป้องกัน | G36: สื่อสารรณรงค์ | H36: T22 ชุดสื่อสร้างความตระหนักรู้ | I36: T10 Application TUM (Tobacco Use Monitor) | J36: ไม่มีเครื่องมือในคลัง | K36: T25; T26 | L36: มีเครื่องมือหลัก | N36: IP-06.pdf
A37: SC-033 | B37: IP-06 | C37: S2 | D37: R13 แกนนำชุมชน | E37: G10 ประชาชนทั่วไป | F37: ดูแลคนที่ใช้แล้ว | G37: สื่อสารรณรงค์ | H37: T22 ชุดสื่อสร้างความตระหนักรู้ | I37: ไม่มีเครื่องมือในคลัง | J37: ไม่มีเครื่องมือในคลัง | K37: - | L37: มีเครื่องมือหลัก | N37: IP-06.pdf
A38: SC-034 | B38: IP-06 | C38: S2 | D38: R14 แกนนำ อปท. | E38: G10 ประชาชนทั่วไป | F38: ป้องกัน | G38: สำรวจสถานการณ์ | H38: T10 Application TUM (Tobacco Use Monitor) | I38: T22 ชุดสื่อสร้างความตระหนักรู้ | J38: T11 แบบสำรวจพฤติกรรมบุหรี่และบุหรี่ไฟฟ้า | K38: T25 | L38: มีเครื่องมือหลัก | N38: IP-06.pdf
A39: SC-035 | B39: IP-06 | C39: S2 | D39: R14 แกนนำ อปท. | E39: G10 ประชาชนทั่วไป | F39: ดูแลคนที่ใช้แล้ว | G39: สื่อสารรณรงค์ | H39: ไม่มีเครื่องมือในคลัง | I39: T22 ชุดสื่อสร้างความตระหนักรู้ | J39: ไม่มีเครื่องมือในคลัง | K39: - | L39: มีเฉพาะเครื่องมือเสริม | M39: บทบาทนี้เป็นผู้ร่วม ไม่ใช่ผู้เริ่ม ระบบควรแนะนำให้ชวนผู้ดำเนินการหลักมาร่วมด้วย | N39: IP-06.pdf
A40: SC-036 | B40: IP-06 | C40: S2 | D40: R18 แกนนำชุมชนมุสลิม | E40: G08 ประชากรกลุ่มเฉพาะ (ชุมชนมุสลิม) | F40: ป้องกัน | G40: ตั้งกติกา/ระบบในองค์กร | H40: T07 แนวปฏิบัติ มัสยิดปลอดบุหรี่ | I40: ไม่มีเครื่องมือในคลัง | J40: ไม่มีเครื่องมือในคลัง | K40: - | L40: มีเครื่องมือหลัก | N40: IP-06.pdf
A41: SC-037 | B41: IP-06 | C41: S2 | D41: R18 แกนนำชุมชนมุสลิม | E41: G08 ประชากรกลุ่มเฉพาะ (ชุมชนมุสลิม) | F41: ดูแลคนที่ใช้แล้ว | G41: ตั้งกติกา/ระบบในองค์กร | H41: T07 แนวปฏิบัติ มัสยิดปลอดบุหรี่ | I41: ไม่มีเครื่องมือในคลัง | J41: ไม่มีเครื่องมือในคลัง | K41: - | L41: มีเครื่องมือหลัก | N41: IP-06.pdf
...

Sheet 04b_ชุดที่ตัดออก
A1: ชุดค่าผสมที่ตัดออกจากการไล่ พร้อมเหตุผล
A2: บันทึกไว้เพื่อให้ตรวจย้อนกลับได้ว่าไม่ได้ตกหล่น
A4: IP | B4: บทบาท | C4: กลุ่มเป้าหมาย | D4: เหตุผลที่ตัด
A5: IP-02 | B5: R02 | C5: G04 | D5: ไม่มีเครื่องมือการเรียนการสอนสำหรับอุดมศึกษาในคลัง จึงให้ไปใช้ IP-01 แทน
A6: IP-04 | B6: R02 | C6: G01/G02 | D6: งานดูแลผู้ที่ใช้แล้วไม่ใช้กับเด็กเล็กและประถม
A7: IP-05 | B7: R18/R19 | C7: G01–G03 | D7: บทบาทศาสนสถานทำงานกับครอบครัวในชุมชนของตน ไม่ได้แยกตามระดับชั้น
A8: IP-06 | B8: R13/R14 | C8: G08 กับ G10 ซ้ำกัน | D8: ถ้าเป็นชุมชนมุสลิมให้ใช้แถว G08 ถ้าชุมชนทั่วไปใช้ G10
A9: IP-07 | B9: R10/R13/R14/R15 | C9: G02–G06 | D9: งานรณรงค์ในเวทีชุมชนนับผู้ร่วมงานเป็นประชาชนทั่วไป
A10: IP-08 | B10: R10/R15/R16 | C10: ระดับป้องกัน | D10: ระบบช่วยเลิกทำงานกับผู้ที่ใช้แล้วเท่านั้น
A11: ทุก IP | B11: R09, R12, R17, R20, R21, R04, R05 | C11: ทุกกลุ่ม | D11: บทบาทที่ไม่มีเครื่องมือหลักรองรับ ตัดออกตาม feedback

Sheet 05_เนื้อหาแผน
A1: เนื้อหาแผนของทั้ง 9 IP ตามโครงสร้าง 18 หัวข้อ
A2: ช่องที่มีป้าย [จำลอง] คือเนื้อหาที่ทีมเขียนขึ้นเพื่อทดสอบระบบ รอแทนที่ด้วยคู่มือจริงจาก สสส.
A4: IP | B4: หัวข้อ | C4: เนื้อหา
A5: IP-01 สถานศึกษาปลอดบุหรี่ไฟฟ้าทั้งระบบ
A6: IP-01 | B6: 1. ชื่อแพ็กเกจ + รหัส | C6: IP-01 สถานศึกษาปลอดบุหรี่ไฟฟ้าทั้งระบบ
A7: IP-01 | B7: 2. เป้าหมายของแพ็กเกจ | C7: สถานศึกษามีนโยบาย คณะทำงาน และสภาพแวดล้อมที่ไม่เอื้อต่อการใช้บุหรี่ไฟฟ้า
A8: IP-01 | B8: 3. สถานการณ์ของคุณ (ตัวอย่าง) | C8: ผู้บริหารโรงเรียนมัธยมต้องการวางระบบทั้งโรงเรียน ไม่ใช่จัดกิจกรรมเป็นครั้ง ๆ
A9: IP-01 | B9: 4. กลุ่มเป้าหมายปลายทาง | C9: นักเรียนประถมปลาย–มัธยม และนักศึกษาอุดมศึกษา
A10: IP-01 | B10: 5. ผู้ดำเนินการหลักและผู้ร่วม | C10: หลัก: ผู้บริหารสถานศึกษา, ทีมผู้บริหารและครู | ร่วม: ครู, บุคลากร, เจ้าหน้าที่สาธารณสุข (ให้คำปรึกษา)
A11: IP-01 | B11: 6. พื้นที่ดำเนินการ | C11: ทั้งโรงเรียน / มหาวิทยาลัย
A12: IP-01 | B12: 7. ระดับ Intervention | C12: ป้องกัน (อุดมศึกษาครอบคลุมการดูแลผู้ที่ใช้แล้วด้วย)
A13: IP-01 | B13: 8. มาตรการที่ผูก (MS) | C13: MS1 นโยบาย, MS2 บริหารจัดการ, MS3 สภาพแวดล้อม
A14: IP-01 | B14: 9. ชุดเครื่องมือ ① ② ③ ④ | C14: ① T01 (อุดมศึกษาใช้ T05, T04) ② T16, T22 ③ T12, T11, T13 ④ T25
A15: IP-01 | B15: 10. เหตุผลที่เลือกเครื่องมือ | C15: T01 เป็นชุดเดียวที่ครอบคลุมนโยบาย คณะทำงาน และสภาพแวดล้อมในเอกสารเดียว ส่วนอุดมศึกษาใช้ T05 เพราะมีขั้นตอนปฏิบัติเฉพาะ [จำลอง]
A16: IP-01 | B16: 11. ขั้นตอนการดำเนินงานรายช่วง | C16: เดือน 1 ประชุมผู้บริหารและตั้งคณะทำงาน | เดือน 2 ประกาศนโยบายและสื่อสารทั่วสถานศึกษา | เดือน 3 สำรวจจุดเสี่ยงและติดตั้งสื่อ | เดือน 4 ประเมินผลและรายงานคณะกรรมการสถานศึกษา [จำลอง]
A17: IP-01 | B17: 12. สิ่งที่ต้องเตรียม | C17: คำสั่งแต่งตั้งคณะทำงาน, เวลาประชุมฝ่าย, งบป้ายและสื่อ [จำลอง]
... A23: IP-01 | B23: 18. รหัสแผน + ช่องทาง feedback | C23: รหัสแผนสร้างอัตโนมัติรูปแบบ SCH-MS1-xxxx + QR ลิงก์แบบติดตามผล
A24: IP-02 ห้องเรียนรู้เท่าทันบุหรี่ไฟฟ้า
A25: IP-02 | B25: 1. ชื่อแพ็กเกจ + รหัส | C25: IP-02 ห้องเรียนรู้เท่าทันบุหรี่ไฟฟ้า
A26: IP-02 | B26: 2. เป้าหมายของแพ็กเกจ | C26: เด็กและเยาวชนมีความรอบรู้และทักษะปฏิเสธเมื่อถูกชักชวน
A27: IP-02 | B27: 3. สถานการณ์ของคุณ (ตัวอย่าง) | C27: ครูประจำชั้น ม.2 พบว่านักเรียนเริ่มถูกเพื่อนชวนใช้บุหรี่ไฟฟ้า
A28: IP-02 | B28: 4. กลุ่มเป้าหมายปลายทาง | C28: เด็กเล็ก (ศพด.), ประถม, มัธยม, อาชีวศึกษา และเยาวชนกลุ่มชาติพันธุ์
A29: IP-02 | B29: 5. ผู้ดำเนินการหลักและผู้ร่วม | C29: หลัก: ครู/อาจารย์ | ร่วม: แกนนำนักเรียน, ผู้ปกครอง, บุคลากรในสถานศึกษา
A30: IP-02 | B30: 6. พื้นที่ดำเนินการ | C30: ห้องเรียน / ศูนย์พัฒนาเด็กเล็ก
A31: IP-02 | B31: 7. ระดับ Intervention | C31: ป้องกัน (กลุ่มอาชีวะใช้ระดับดูแลผู้ที่ใช้แล้ว)
A32: IP-02 | B32: 8. มาตรการที่ผูก (MS) | C32: MS4 การสอดแทรกในการเรียนการสอน
A33: IP-02 | B33: 9. ชุดเครื่องมือ ① ② ③ ④ | C33: ① เด็กเล็ก T24 / ประถม T08 / มัธยม T18 / อาชีวะ T19 ② T16, T08, T20 ③ T12, T09, T14 ④ T26
A34: IP-02 | B34: 10. เหตุผลที่เลือกเครื่องมือ | C34: เลือกตามระดับชั้นเพราะเครื่องมือแต่ละชิ้นระบุกลุ่มเป้าหมายไว้ชัดในตาราง Flagship 11 พ.ค.
A35: IP-02 | B35: 11. ขั้นตอนการดำเนินงานรายช่วง | C35: สัปดาห์ 1 ประเมินความรอบรู้ก่อนเริ่ม | สัปดาห์ 2–4 จัดกิจกรรมตามเครื่องมือหลัก | เดือน 2 ส่งกิจกรรมให้ผู้ปกครองทำต่อที่บ้าน | เดือน 3 ประเมินซ้ำและสรุปให้ฝ่ายวิชาการ [จำลอง]
A36: IP-02 | B36: 12. สิ่งที่ต้องเตรียม | C36: ชุดเครื่องมือตามจำนวนกลุ่ม, คาบกิจกรรม 1–2 คาบ, ครูผู้นำกิจกรรม [จำลอง]
... A42: IP-02 | B42: 18. รหัสแผน + ช่องทาง feedback | C42: รหัสแผน SCH-MS4-xxxx + QR ลิงก์แบบติดตามผล
A43: IP-03 แกนนำเยาวชนขับเคลื่อนเอง
A44: IP-03 | B44: 1. ชื่อแพ็กเกจ + รหัส | C44: IP-03 แกนนำเยาวชนขับเคลื่อนเอง
A45: IP-03 | B45: 2. เป้าหมายของแพ็กเกจ | C45: มีชมรมหรือแกนนำที่ออกแบบและจัดกิจกรรมเรื่องบุหรี่ไฟฟ้าได้เอง
A46: IP-03 | B46: 3. สถานการณ์ของคุณ (ตัวอย่าง) | C46: แกนนำนักเรียนอยากตั้งชมรมเพื่อทำงานเรื่องนี้ต่อเนื่อง ไม่ใช่กิจกรรมครั้งเดียว
A47: IP-03 | B47: 4. กลุ่มเป้าหมายปลายทาง | C47: เพื่อนนักเรียนมัธยม, นักศึกษาอุดมศึกษา, เยาวชนนอกระบบการศึกษา
A48: IP-03 | B48: 5. ผู้ดำเนินการหลักและผู้ร่วม | C48: หลัก: แกนนำนักเรียน, แกนนำนักศึกษา | ร่วม: ครูที่ปรึกษาชมรม
A49: IP-03 | B49: 6. พื้นที่ดำเนินการ | C49: ชมรมในสถานศึกษา / ศูนย์การเรียนรู้
A50: IP-03 | B50: 7. ระดับ Intervention | C50: ป้องกัน
A51: IP-03 | B51: 8. มาตรการที่ผูก (MS) | C51: MS5 การมีส่วนร่วมของนักเรียน
...

Sheet 06_ช่องว่างและตัวเลขสรุป
A1: ตัวเลขสรุปสำหรับคุยกับลูกค้า และรายการช่องว่างของคลัง
A2: ตัวเลขทั้งหมดคำนวณจากชีต 04 ไม่ได้พิมพ์มือ
A4: ตัวเลขหลัก
A5: ประเด็น | B5: จำนวน | C5: อ่านว่าอย่างไร
A6: สถานการณ์ที่ระบบต้องรองรับทั้งหมด | B6: =COUNTA(04_สถานการณ์!A5:A58) -> 54 | C6: ทุกชุดค่าผสมของ IP × บทบาท × กลุ่มเป้าหมาย × ระดับ ที่เป็นไปได้จริง
A7: สถานการณ์ที่มีเครื่องมือหลักรองรับ | B7: =COUNTIF(04_สถานการณ์!L5:L58,"มีเครื่องมือหลัก") -> 41 | C7: ผู้ใช้ได้แผนที่มีเครื่องมือให้เริ่มทำทันที
A8: สถานการณ์ที่มีเฉพาะเครื่องมือเสริม | B8: =COUNTIF(04_สถานการณ์!L5:L58,"มีเฉพาะเครื่องมือเสริม") -> 10 | C8: บทบาทนั้นเป็นผู้ร่วม ไม่ใช่ผู้เริ่ม ระบบต้องแนะนำให้ชวนผู้ดำเนินการหลักมาร่วม
A9: สถานการณ์ที่ไม่มีเครื่องมือเลย | B9: =COUNTIF(04_สถานการณ์!L5:L58,"ไม่มีเครื่องมือในคลัง") -> 3 | C9: ช่องว่างของคลัง ต้องขอเครื่องมือเพิ่มจาก สสส.
A10: เครื่องมือในคลังที่ใช้งานได้ | B10: =25 -> 25 | C10: จาก 28 ชิ้น ตัดชั่วคราว 3 ชิ้นตาม feedback
A11: เครื่องมือลงมือทำที่ถูกใช้เป็นเครื่องมือหลักอย่างน้อย 1 สถานการณ์ | B11: =18 -> 18 | C11: ครบทั้ง 18 ชิ้น ไม่มีชิ้นไหนตกหล่น ส่วนอีก 7 ชิ้นเป็นแบบประเมิน (T09, T11–T14) และข้อมูลอ้างอิง (T25, T26) ซึ่งอยู่ในช่อง ③ และ ④
A12: บทบาทที่เปิดใช้ในระบบ | B12: =16 -> 16 | C12: จาก 24 บทบาท ตัดบทบาทที่ไม่มีเครื่องมือหลักตาม feedback
A13: แพ็กเกจแผน (IP) | B13: =9 -> 9 | C13: 8 แพ็กเกจตามโมเดล + 1 แพ็กเกจสถานประกอบการที่ไม่มีในโมเดล
A16: รายการช่องว่างที่ต้องขอเพิ่มจาก สสส.
A17: ช่องว่าง | B17: อยู่ที่ IP ไหน | C17: ผลต่อผู้ใช้ | D17: ความสำคัญ
A18: ไม่มีเครื่องมือดูแลผู้ที่ใช้แล้วสำหรับนักเรียนมัธยม | B18: IP-04 | C18: ครูที่เจอนักเรียนมัธยมใช้บุหรี่ไฟฟ้าได้แค่คำแนะนำให้ส่งต่อ ไม่มีเครื่องมือในมือ | D18: สูง
A19: ไม่มีเครื่องมือสำหรับเด็กเล็กที่บ้าน | B19: IP-05 | C19: ผู้ปกครองเด็กเล็กได้เฉพาะเครื่องมือของครู ศพด. ซึ่งไม่ได้ออกแบบให้พ่อแม่ใช้เอง | D19: สูง
A20: ไม่มีเครื่องมือเฝ้าระวังร้านค้าและการขายออนไลน์ | B20: IP-06 | C20: ชุมชนประกาศเขตปลอดบุหรี่ได้ แต่จัดการแหล่งขายรอบพื้นที่เด็กไม่ได้ | D20: สูง
A21: ไม่มีเครื่องมือระดับดูแลผู้ที่ใช้แล้วสำหรับวัยทำงาน | B21: IP-09 | C21: พนักงานที่อยากเลิกต้องพึ่งการส่งต่อออกนอกองค์กรอย่างเดียว | D21: สูง
A22: มาตรการ MS2 และ MS3 ไม่มีเครื่องมือเฉพาะ | B22: IP-01 | C22: ผู้บริหารได้เพียงหัวข้อกว้าง ๆ ไม่มีเช็กลิสต์สำรวจจุดเสี่ยงหรือแบบฟอร์มคณะทำงาน | D22: กลาง
A23: ไม่มีแนวปฏิบัติสำหรับวัด มีเฉพาะมัสยิด | B23: IP-06 | C23: ชุมชนพุทธใช้ IP-06 ได้ไม่เต็มที่ | D23: กลาง
A24: ไม่มีคู่มือขั้นตอนตั้งชมรม | B24: IP-03 | C24: แกนนำได้ชื่อกลไกแต่ไม่มีขั้นตอนให้ทำตาม | D24: กลาง
A25: แกนนำชุมชนไม่มีเครื่องมือหลักในบริบทชุมชนมุสลิม | B25: IP-06 | C25: ต้องรอคณะกรรมการมัสยิดเป็นผู้เริ่มเสมอ | D25: กลาง
A26: ไม่มีแบบประเมินสำหรับเด็กเล็กและระดับครัวเรือน | B26: IP-02, IP-05 | C26: วัดผลไม่ได้ในสองแพ็กเกจนี้ | D26: กลาง
A27: ยังไม่มีคู่มือจริงของเครื่องมือทุกชิ้น | B27: ทุก IP | C27: หัวข้อ 11–15 ของไฟล์แผนยังเป็นเนื้อหาจำลอง | D27: สูง

Sheet 07_ข้อมูลที่ต้องขอ
A1: ข้อมูลที่ต้องขอจาก สสส. เพื่อแทนที่ข้อมูลจำลอง
A2: เรียงตามความจำเป็น 3 ระดับ ใช้เป็นต้นทางของแบบขอข้อมูล (ไฟล์ 5)
A4: ระดับ | B4: ข้อมูลที่ขอ | C4: ใช้แทนที่อะไรในไฟล์นี้ | D4: ถ้าไม่ได้จะเกิดอะไร
A5: 1 ขาดไม่ได้ | B5: ไฟล์เครื่องมือจริง 25 ชิ้น พร้อมสิทธิ์เผยแพร่ | C5: ไฟล์การ์ด T01–T28 และปุ่มดาวน์โหลดในเว็บ | D5: ผู้ใช้ดาวน์โหลดได้แต่เอกสารจำลอง ส่งมอบจริงไม่ได้
A6: 1 ขาดไม่ได้ | B6: ขั้นตอนการใช้เครื่องมือแต่ละชิ้น อย่างน้อย 3–4 ช่วง | C6: ชีต 02 คอลัมน์ขั้นตอนใช้งาน [จำลอง] | D6: แผนที่ผู้ใช้ได้รับไม่ตรงกับวิธีใช้จริงของเครื่องมือ
A7: 1 ขาดไม่ได้ | B7: เส้นทางส่งต่อเมื่อพบผู้ใช้บุหรี่ไฟฟ้า แยกตามพื้นที่ | C7: หัวข้อ 16 ของทุก IP | D7: ระบบแนะนำให้ส่งต่อแต่ไม่รู้ว่าส่งไปที่ไหน
A8: 1 ขาดไม่ได้ | B8: ยืนยันผู้ดำเนินการและกลุ่มเป้าหมายของแต่ละเครื่องมือ | C8: ชีต 02 และ 04 ทั้งหมด | D8: การจับคู่อาจผิด ทำให้แนะนำเครื่องมือที่ใช้ไม่ได้จริง
A9: 2 จำเป็นต่อคุณภาพ | B9: ความเสี่ยง เงื่อนไขความสำเร็จ และตัวชี้วัดของแต่ละเครื่องมือ | C9: ชีต 02 และหัวข้อ 13–15 ของทุก IP | D9: แผนมีครบทุกหัวข้อแต่เนื้อหายังเป็นของทีม ไม่ใช่ของ สสส.
A10: 2 จำเป็นต่อคุณภาพ | B10: คำตอบเรื่อง T02 G-RDU, T03 CIB, T17 Survival Kit ว่าเกี่ยวกับบุหรี่ไฟฟ้าหรือไม่ | C10: ชีต 00 และช่องว่างของ IP-05, IP-06 | D10: ถ้าเกี่ยวจริง แปลว่าเราตัดเครื่องมือที่ใช้ได้ออกไป 3 ชิ้น
A11: 2 จำเป็นต่อคุณภาพ | B11: รายละเอียด 7 องค์ประกอบ (อุดมศึกษา) และ 7 ชุดกิจกรรม | C11: T01 และ T15 | D11: สองชิ้นนี้ยังแนะนำแบบกว้าง ไม่มีเนื้อหาให้ผู้ใช้ทำตาม
A12: 2 จำเป็นต่อคุณภาพ | B12: ยืนยันว่า T15 ใช้กับชุมชนหรือ ศพด. | C12: IP-07 | D12: อาจแนะนำผิดพื้นที่
A13: 3 เติมให้สมบูรณ์ | B13: ตัวเลขสถานการณ์บุหรี่ไฟฟ้าพร้อมแหล่งอ้างอิง | C13: ส่วน C ของหน้าเว็บ | D13: หน้าเว็บยังเว้นวงเล็บเหลี่ยมไว้
A14: 3 เติมให้สมบูรณ์ | B14: โลโก้ สสส. และภาคี พร้อมสิทธิ์การใช้ | C14: ส่วน A และ E ของหน้าเว็บ | D14: ใช้กล่องว่างแทนโลโก้
A15: 3 เติมให้สมบูรณ์ | B15: เครื่องมือใหม่ที่ยังไม่มีในคลัง ตามรายการช่องว่างในชีต 06 | C15: 10 รายการช่องว่าง | D15: ผู้ใช้บางกลุ่มยังได้แผนที่ไม่มีเครื่องมือให้เริ่ม
